<mujoco>

   <body mocap="true" name="robot0:mocap" pos="1 1 1">
	   <geom conaffinity="0" contype="0" pos="0 0 0" rgba="1 0 0 1" size="1 1 1" type="box"></geom>
	   <geom conaffinity="0" contype="0" pos="0 0 0" rgba="1 0 0 .6" size="100 1 1" type="box"></geom>
	   <geom conaffinity="0" contype="0" pos="0 0 0" rgba="1 0 0 .6" size="1 100 1" type="box"></geom>
	   <geom conaffinity="0" contype="0" pos="0 0 0" rgba="1 0 0 .6" size="1 1 100" type="box"></geom>
   </body>

   <body childclass="robot0:harold" name="robot0:base_link" pos="0 0 0" quat="1 1 0 0">
	   <geom mesh="robot0:rotary_base" name="robot0:rotary_base" material="robot0:base_mat" class="robot0:grey" density="1240"></geom>
      <body name="robot0:rotary_plate" pos="0 69.5 0">
         <geom density="1240" mesh="robot0:rotary_plate" name="robot0:rotary_plate" material="robot0:base_mat" class="robot0:blue"></geom>
         <joint name="robot0:rotator" pos="0 -65 0" axis="0 1 0" type="hinge"></joint>
         <body name="robot0:shoulder" pos="-80 42 80">
            <geom density="1240" mesh="robot0:shoulder_base" material="robot0:base_mat"></geom>
            <body name="robot0:shoulder_joint" pos="80 120.1 -80">
               <geom density="1240" mesh="robot0:shoulder_joint_1" material="robot0:base_mat" quat=".5 .5 -.5 .5" class="robot0:blue"></geom>
               <geom density="1240" mesh="robot0:shoulder_joint_2" material="robot0:base_mat" quat=".5 .5 .5 -.5" class="robot0:blue"></geom>
               <joint name="robot0:shoulder_joint" pos="-78 0 0" axis="1 0 0" type="hinge" limited="true" range="-2.04 2.04"></joint>
               <body name="robot0:elbow_base" pos="-65 79 -42.5">
                  <geom density="1240" mesh="robot0:elbow_base" material="robot0:base_mat"></geom>
                  <body name="robot0:elbow_joint" pos="65 270.15 7.5">
                     <geom density="1240" mesh="robot0:elbow_joint_half_1" material="robot0:base_mat" class="robot0:blue" pos="0 0 70" quat="0.707 0 0 -.707"></geom>
                     <geom density="1240" mesh="robot0:elbow_joint_half_2" material="robot0:base_mat" class="robot0:blue" quat="0 -.707 .707 -0"></geom>
                     <joint name="robot0:elbow_joint" pos="-75 -127.5 35" axis="1 0 0" type="hinge" limited="true" range="-2.2 2.2"></joint>
                     <body name="robot0:wrist_base" pos="-45 0.5 0" quat="0.707 0 0.707 0">
                        <geom density="1240" mesh="robot0:wrist_base" material="robot0:base_mat"></geom>
                        <body name="robot0:wrist_joint" pos="-35 95 45" quat=".707 0 -.707 0">
                           <geom density="1240" mesh="robot0:wrist_half_1" class="robot0:blue" material="robot0:base_mat" quat="0.5 0.5 -0.5 0.5"></geom>
                           <geom density="1240" mesh="robot0:wrist_half_2" class="robot0:blue" material="robot0:base_mat" quat="0.5 0.5 0.5 -0.5"></geom>
                           <joint name="robot0:wrist_joint" pos="-75 0 0" axis="1 0 0" type="hinge" limited="true" range="-2 2"></joint>
                           <body name="robot0:hand" pos="0 90.5 0">
                              <geom density="1240" mesh="robot0:gripper_top_plate" pos="-30 0 -3.5" quat="0.707 -0.707 0 0"></geom>
                              <geom density="1240" mesh="robot0:gripper_bottom_plate" pos="30 0 3.5" quat="0 0 0.707 0.707"></geom>
                              <site name="robot0:gripper"></site>
                              <body name="robot0:gripper_gear_b" pos="-54 -25 -3">
                                 <geom density="1240" mesh="robot0:servo_gear_b" quat="0.707 0.707 0 0" gap="100"></geom>
                                 <joint name="robot0:servo_gear_b" pos="40 0 -70" type="hinge" limited="true" range="-1.6 .6"></joint>
                                    <body name="robot0:finger_left" pos="13 -10 -6">
                                       <geom density="1240" mesh="robot0:gripper_left" quat=".5 .5 .5 .5"></geom>
                                       <joint name="robot0:finger_left" pos="-13 10 -62.5" type="hinge"></joint>
                                    </body>
                              </body>
                              <body name="robot0:servo_gear_a" pos="54 -25 3">
                                 <geom density="1240" mesh="robot0:servo_gear_a" quat="0 0 .707 -.707" gap="100"></geom>
                                 <joint name="robot0:servo_gear_a" pos="-40 0 -72.5" type="hinge"></joint>
                                    <body name="robot0:finger_right" pos="-13 -10 6">
                                       <geom density="1240" mesh="robot0:gripper_right" quat=".5 -.5 -.5 .5"></geom>
                                       <joint name="robot0:finger_right" type="hinge" pos="13 10 -75"></joint>
                                    </body>
                              </body>
                              <body name="robot0:pivot_arm_a" pos="7 -5 -3.25">
                                 <geom density="1240" mesh="robot0:pivot_arm_b" quat="0.707 0.707 0 0" gap="100"></geom>
                                 <joint name="robot0:pivot_arm_a" pos="0 0 -60" type="hinge"></joint>
                              </body>
                              <body name="robot0:pivot_arm_b" pos="-47 -5 -3.25">
                                 <geom density="1240" mesh="robot0:pivot_arm_b" quat="0.707 0.707 0 0" gap="100"></geom>
                                 <joint name="robot0:pivot_arm_b" pos="40 0 -60" type="hinge"></joint>
                              </body>
                           </body>
                        </body>
                     </body>
                  </body>
               </body>
            </body>
         </body>
      </body>
   </body>
</mujoco>
