<mujoco>

	<body mocap="true" name="robot0:mocap" pos="0 0 0">
		<geom conaffinity="0" contype="0" pos="0 0 0" rgba="0 0.5 0 0.7" size="0.005 0.005 0.005" type="box"></geom>
		<geom conaffinity="0" contype="0" pos="0 0 0" rgba="0 0.5 0 0.1" size="1 0.005 0.005" type="box"></geom>
		<geom conaffinity="0" contype="0" pos="0 0 0" rgba="0 0.5 0 0.1" size="0.005 1 0.005" type="box"></geom>
		<geom conaffinity="0" contype="0" pos="0 0 0" rgba="0 0.5 0 0.1" size="0.005 0.005 1" type="box"></geom>
	</body>

   <body childclass="robot0:harold" name="robot0:base_link" pos="0 0 0" quat="1 1 0 0">
	   <geom mesh="robot0:rotary_base" name="robot0:rotary_base" material="robot0:base_mat" class="robot0:grey"></geom>
      <body name="robot0:rotary_plate">
         <geom mesh="robot0:rotary_plate" name="robot0:rotary_plate" material="robot0:base_mat" class="robot0:blue" pos="0 69.5 0"></geom>
         <joint name="robot0:rotator" axis="0 1 0" type="hinge"></joint>
         <body name="robot0:shoulder">
            <geom mesh="robot0:shoulder_base" pos="-80 111 80" material="robot0:base_mat"></geom>
            <body name="robot0:shoulder_joint">
               <geom mesh="robot0:shoulder_joint_1" material="robot0:base_mat" pos="0 231 0" quat=".5 .5 -.5 .5" class="robot0:blue"></geom>
               <geom mesh="robot0:shoulder_joint_2" material="robot0:base_mat" pos="0 231 0" quat=".5 .5 .5 -.5" class="robot0:blue"></geom>
               <joint name="robot0:shoulder_joint" pos="0 231 0" axis="1 0 0" type="hinge"></joint>
               <body name="robot0:elbow_base">
                  <geom mesh="robot0:elbow_base" material="robot0:base_mat" pos="-65 310 -42.5"></geom>
                  <body name="robot0:elbow_joint">
                     <geom mesh="robot0:elbow_joint_half_1" material="robot0:base_mat" class="robot0:blue" quat="0.707 0 0 -.707" pos="0 580.2 35"></geom>
                     <geom mesh="robot0:elbow_joint_half_2" material="robot0:base_mat" class="robot0:blue" quat="0 -.707 .707 -0" pos="0 580.2 -35"></geom>
                     <joint name="robot0:elbow_joint" pos="0 452.5 0" axis="1 0 0" type="hinge"></joint>
                     <body name="robot0:wrist_base">
                        <geom mesh="robot0:wrist_base" material="robot0:base_mat" pos="-45 580.5 -35" quat="0.707 0 0.707 0"></geom>
                        <body name="robot0:wrist_joint">
                           <geom mesh="robot0:wrist_half_1" class="robot0:blue" material="robot0:base_mat" pos="0 675.5 0" quat="0.5 0.5 -0.5 0.5"></geom>
                           <geom mesh="robot0:wrist_half_2" class="robot0:blue" material="robot0:base_mat" pos="0 675.5 0" quat="0.5 0.5 0.5 -0.5"></geom>
                           <joint name="robot0:wrist_joint" pos="0 675.5 0" axis="1 0 0" type="hinge"></joint>
                           <body name="robot0:hand">
                              <geom mesh="robot0:gripper_top_plate" pos="-30 766 -3" quat="0.707 -0.707 0 0"></geom>
                              <geom mesh="robot0:gripper_bottom_plate" pos="30 766 3.6" quat="0 0 0.707 0.707"></geom>
                              <body name="robot0:gripper_gear_a">
                                 <geom mesh="robot0:servo_gear_a" pos="54.5 741 3.25" quat="0 0 -0.707 0.707" gap="1"></geom>
                                 <joint name="robot0:servo_gear_a" pos="14.5 741 3.25" type="hinge"></joint>
                                    <body name="robot0:finger_right">
                                       <geom mesh="robot0:gripper_right" pos="41 731 9" quat="-0.5 0.5 0.5 -0.5"></geom>
                                       <joint name="robot0:finger_right" pos="53 740 0" type="hinge"></joint>
                                    </body>
                              </body>
                              <body name="robot0:servo_gear_b">
                                 <geom mesh="robot0:servo_gear_b" pos="-54.5 741 3.25" quat="0.707 -0.707 0 0" gap="1"></geom>
                                 <joint name="robot0:servo_gear_b" pos="-14.5 741 3.25" type="hinge"></joint>
                                    <body name="robot0:finger_left">
                                       <geom mesh="robot0:gripper_left" pos="-41 731 -9" quat="0.5 0.5 0.5 0.5"></geom>
                                       <joint name="robot0:finger_left" type="hinge" pos="-53 740 0"></joint>
                                    </body>
                              </body>
                              <body name="robot0:pivot_arm_a">
                                 <geom mesh="robot0:pivot_arm_b" pos="7 761 -3.25" quat="0.707 0.707 0 0" gap="100"></geom>
                                 <joint name="robot0:pivot_arm_a" pos="7 761 -3.25" type="hinge"></joint>
                              </body>
                              <body name="robot0:pivot_arm_b">
                                 <geom mesh="robot0:pivot_arm_b" pos="-47 761 -3.25" quat="0.707 0.707 0 0" gap="100"></geom>
                                 <joint name="robot0:pivot_arm_b" pos="-7 761 -3.25" type="hinge"></joint>
                              </body>
                           </body>
                        </body>
                     </body>
                  </body>
               </body>
            </body>
         </body>
      </body>
   </body>
</mujoco>
